<?xml version="1.0"?>

<robot name="opcional">

    <link name="base">
        <visual>
            <origin xyz="0 0 0" />
            <geometry>
                <box size="0.4 0.4 0.2" />
            </geometry>
        </visual>
        <collision>
            <origin xyz="0 0 0" />
            <geometry>
             <box size="0.4 0.4 0.2" />
            </geometry>
        </collision>



    </link>

    <link name="linkVertical">
        <visual>
            <origin xyz="0 0 0" />
            <geometry>
                <box size="0.2 0.2 1" />
            </geometry>
        </visual>
        <collision>
            <origin xyz="0 0 0" />
            <geometry>
             <box size="0.2 0.2 1" />
            </geometry>
        </collision>



    </link>

    <link name="linkHorizontal">
        <visual>
            <origin xyz="0.3 0 0" />
            <geometry>
                <box size="0.8 0.2 0.2" />
            </geometry>
        </visual>
        <collision>
            <origin xyz="0.3 0 0" />
            <geometry>
             <box size="0.8 0.2 0.2" />
            </geometry>
        </collision>



    </link>


    <joint name="base_to_vertical" type="continuous">
        <parent link="base" />
        <child link="linkVertical" />
        <dynamics damping="0.0" friction="0.00001" />
        <origin xyz="0 0 0.5" />
        <axis xyz="0 1 0" />

       
    </joint>


     <joint name="vertical_to_horizontal" type="continuous">
        <parent link="linkVertical" />
        <child link="linkHorizontal" />
        <dynamics damping="0.0" friction="0.00001" />
        <origin xyz="0 0 0.5" />
        <axis xyz="0 0 1" />

        
    </joint>

</robot>